Workbook

Sheet Tableau de bord
A1: TABLEAU DE BORD BOM
A4: Indicateur | B4: Projet 1 | C4: Projet 2 | D4: Total
A5: Coût total du projet (FCFA) | B5: ='Projet 1'!E51 -> 553216 | C5: ='Projet 2'!E51 -> 14100 | D5: =B5+C5 -> 567316
A7: Répartition du coût par catégorie (FCFA)
A8: Catégorie | B8: Projet 1 | C8: Projet 2 | D8: Total
A9: Cartes de développement & microprocesseurs | B9: ='Projet 1'!E19 -> 345009 | C9: ='Projet 2'!E19 -> 4500 | D9: =B9+C9 -> 349509
A10: Antennes & connectivité | B10: ='Projet 1'!E29 -> 175117 | C10: ='Projet 2'!E29 -> 6400 | D10: =B10+C10 -> 181517
A11: Alimentations | B11: ='Projet 1'!E39 -> 29490 | C11: ='Projet 2'!E39 -> 1800 | D11: =B11+C11 -> 31290
A12: Capteurs & accessoires | B12: ='Projet 1'!E49 -> 3600 | C12: ='Projet 2'!E49 -> 1400 | D12: =B12+C12 -> 5000
A14: Ces indicateurs se recalculent automatiquement dès que les feuilles « Projet 1 » ou « Projet 2 » sont modifiées.

Sheet Projet 1
A1: BILL OF MATERIALS (BOM) — [Nom du projet 1]
A3: Nomenclature des composants classée par catégorie — Fiche d'approvisionnement automatisée
A5: Projet | C5: [Nom du projet 1]
A6: Référence BOM | C6: [Ex: BOM-2026-001]
A7: Date | C7: [JJ/MM/AAAA]
A8: Version | C8: [V1.0]
A9: Préparé par | C9: [Nom du responsable]
A11: ▸ Cartes de développement & microprocesseurs
A12: N° | B12: Désignation | C12: Qté | D12: Prix unitaire (FCFA) | E12: Prix total (FCFA) | F12: Image | G12: Lien AliExpress
A13: =ROW()-12 -> 1 | B13: Kit de démarrage complet Raspberry Pi 4 d'origine avec 1 Go/2 Go/4 Go/8 Go de RAM, carte d'extension GPIO, USB 3.0 pour l'IA, la vision et la robotique | C13: 3 | D13: 115003 | E13: =IF(OR(C13="",D13=""),"",C13*D13) -> 345009 | G13: lien vers le produit
A14: =ROW()-12 -> 2 | B14: Kit Seeed XIAO NRF52840 & Wio-SX1262 pour Meshtastic, LoRa 862-930MHz, 868MHz, 915MHz, antenne intégrée, microcontrôleur Bluetooth | C14: 5 | E14: =IF(OR(C14="",D14=""),"",C14*D14) | F14: Coller image ici
A15: =ROW()-12 -> 3 | E15: =IF(OR(C15="",D15=""),"",C15*D15) | F15: Coller image ici
A16: =ROW()-12 -> 4 | E16: =IF(OR(C16="",D16=""),"",C16*D16) | F16: Coller image ici
A17: =ROW()-12 -> 5 | E17: =IF(OR(C17="",D17=""),"",C17*D17) | F17: Coller image ici
A18: =ROW()-12 -> 6 | E18: =IF(OR(C18="",D18=""),"",C18*D18) | F18: Coller image ici
B19: Sous-total catégorie | C19: =SUM(C13:C18) -> 8 | E19: =SUM(E13:E18) -> 345009
A21: ▸ Antennes & connectivité
A22: N° | B22: Désignation | C22: Qté | D22: Prix unitaire (FCFA) | E22: Prix total (FCFA) | F22: Image | G22: Lien AliExpress
A23: =ROW()-22 -> 1 | B23: SIM7600G-H Waveshare 4G HAT (B) pour Raspberry Pi 5 LTE Cat-4 4G / 3G / 2G Support, positionnement GNSS, bande globale | C23: 2 | D23: 40753 | E23: =IF(OR(C23="",D23=""),"",C23*D23) -> 81506 | G23: https://aliexpress.com/item/EXEMPLE-ANTENNE
A24: =ROW()-22 -> 2 | B24: Module de passerelle LoRaWAN LR1302 SPI EU868 SX1302 longue portée, prend en charge 8 canaux | C24: 2 | D24: 11141 | E24: =IF(OR(C24="",D24=""),"",C24*D24) -> 22282 | G24: lien vers le produit
A25: =ROW()-22 -> 3 | B25: Chapeau LoRaWAN LR1302, 868m/915m, pour RPI SX1302, technologie longue portée avec GPS + BD, antenne en mode touristes, support RPi série 1 2 3 4 5 | C25: 2 | D25: 21108 | E25: =IF(OR(C25="",D25=""),"",C25*D25) -> 42216 | G25: Lien vers le produit
A26: =ROW()-22 -> 4 | B26: Lora Gateway antenne 433 868 915 Mhz 3Dbi 5Dbi 5.8Dbi 8Dbi 10Dbi 12Dbi,/Bobcat300/Nebra antenne en fibre de verre | C26: 3 | D26: 8139 | E26: =IF(OR(C26="",D26=""),"",C26*D26) -> 24417 | F26: Coller image ici | G26: lien vers le produit
A27: =ROW()-22 -> 5 | B27: Câbles coaxiaux de type N femelle de 15 cm, U.FL IP1 vers N femelle, câble coaxial RG178 pour routeur T-Mobile, antenne, cartes Mini PCIE, Wi-Fi WLAN | C27: 4 | D27: 1174 | E27: =IF(OR(C27="",D27=""),"",C27*D27) -> 4696 | F27: Coller image ici | G27: lien vers le produit
A28: =ROW()-22 -> 6 | E28: =IF(OR(C28="",D28=""),"",C28*D28) | F28: Coller image ici
B29: Sous-total catégorie | C29: =SUM(C23:C28) -> 13 | E29: =SUM(E23:E28) -> 175117
A31: ▸ Alimentations
A32: N° | B32: Désignation | C32: Qté | D32: Prix unitaire (FCFA) | E32: Prix total (FCFA) | F32: Image | G32: Lien AliExpress
A33: =ROW()-32 -> 1 | B33: Module de gestion d'énergie solaire Waveshare (D), prend en charge les panneaux solaires 6V~24V et l'adaptateur d'alimentation Type-C, 5V/3A, pour Raspberry Pi/Ardruino | C33: 5 | D33: 5898 | E33: =IF(OR(C33="",D33=""),"",C33*D33) -> 29490 | F33: Coller image ici | G33: Lien vers le produit
A34: =ROW()-32 -> 2 | E34: =IF(OR(C34="",D34=""),"",C34*D34)
A35: =ROW()-32 -> 3 | E35: =IF(OR(C35="",D35=""),"",C35*D35) | F35: Coller image ici
A36: =ROW()-32 -> 4 | E36: =IF(OR(C36="",D36=""),"",C36*D36) | F36: Coller image ici
A37: =ROW()-32 -> 5 | E37: =IF(OR(C37="",D37=""),"",C37*D37) | F37: Coller image ici
A38: =ROW()-32 -> 6 | E38: =IF(OR(C38="",D38=""),"",C38*D38) | F38: Coller image ici
B39: Sous-total catégorie | C39: =SUM(C33:C38) -> 5 | E39: =SUM(E33:E38) -> 29490
A41: ▸ Capteurs & accessoires
A42: N° | B42: Désignation | C42: Qté | D42: Prix unitaire (FCFA) | E42: Prix total (FCFA) | F42: Image | G42: Lien AliExpress
A43: =ROW()-42 -> 1 | B43: Capteur de courant SCT-013-030 | C43: 2 | D43: 1800 | E43: =IF(OR(C43="",D43=""),"",C43*D43) -> 3600 | F43: Coller image ici | G43: https://aliexpress.com/item/EXEMPLE-SCT013
A44: =ROW()-42 -> 2 | E44: =IF(OR(C44="",D44=""),"",C44*D44) | F44: Coller image ici
A45: =ROW()-42 -> 3 | E45: =IF(OR(C45="",D45=""),"",C45*D45) | F45: Coller image ici
A46: =ROW()-42 -> 4 | E46: =IF(OR(C46="",D46=""),"",C46*D46) | F46: Coller image ici
...

Sheet Projet 2
A1: BILL OF MATERIALS (BOM) — [Nom du projet 2]
A3: Nomenclature des composants classée par catégorie — Fiche d'approvisionnement automatisée
A5: Projet | C5: [Nom du projet 2]
A6: Référence BOM | C6: [Ex: BOM-2026-001]
A7: Date | C7: [JJ/MM/AAAA]
A8: Version | C8: [V1.0]
A9: Préparé par | C9: [Nom du responsable]
A11: ▸ Cartes de développement & microprocesseurs
A12: N° | B12: Désignation | C12: Qté | D12: Prix unitaire (FCFA) | E12: Prix total (FCFA) | F12: Image | G12: Lien AliExpress
A13: =ROW()-12 -> 1 | B13: Raspberry Pi Pico W | C13: 1 | D13: 4500 | E13: =IF(OR(C13="",D13=""),"",C13*D13) -> 4500 | F13: Coller image ici | G13: https://aliexpress.com/item/EXEMPLE-PICO
A14: =ROW()-12 -> 2 | E14: =IF(OR(C14="",D14=""),"",C14*D14) | F14: Coller image ici
A15: =ROW()-12 -> 3 | E15: =IF(OR(C15="",D15=""),"",C15*D15) | F15: Coller image ici
A16: =ROW()-12 -> 4 | E16: =IF(OR(C16="",D16=""),"",C16*D16) | F16: Coller image ici
A17: =ROW()-12 -> 5 | E17: =IF(OR(C17="",D17=""),"",C17*D17) | F17: Coller image ici
A18: =ROW()-12 -> 6 | E18: =IF(OR(C18="",D18=""),"",C18*D18) | F18: Coller image ici
B19: Sous-total catégorie | C19: =SUM(C13:C18) -> 1 | E19: =SUM(E13:E18) -> 4500
A21: ▸ Antennes & connectivité
A22: N° | B22: Désignation | C22: Qté | D22: Prix unitaire (FCFA) | E22: Prix total (FCFA) | F22: Image | G22: Lien AliExpress
A23: =ROW()-22 -> 1 | B23: Module LoRa SX1276 433MHz | C23: 2 | D23: 3200 | E23: =IF(OR(C23="",D23=""),"",C23*D23) -> 6400 | F23: Coller image ici | G23: https://aliexpress.com/item/EXEMPLE-LORA
A24: =ROW()-22 -> 2 | E24: =IF(OR(C24="",D24=""),"",C24*D24) | F24: Coller image ici
A25: =ROW()-22 -> 3 | E25: =IF(OR(C25="",D25=""),"",C25*D25) | F25: Coller image ici
A26: =ROW()-22 -> 4 | E26: =IF(OR(C26="",D26=""),"",C26*D26) | F26: Coller image ici
A27: =ROW()-22 -> 5 | E27: =IF(OR(C27="",D27=""),"",C27*D27) | F27: Coller image ici
A28: =ROW()-22 -> 6 | E28: =IF(OR(C28="",D28=""),"",C28*D28) | F28: Coller image ici
B29: Sous-total catégorie | C29: =SUM(C23:C28) -> 2 | E29: =SUM(E23:E28) -> 6400
A31: ▸ Alimentations
A32: N° | B32: Désignation | C32: Qté | D32: Prix unitaire (FCFA) | E32: Prix total (FCFA) | F32: Image | G32: Lien AliExpress
A33: =ROW()-32 -> 1 | B33: Batterie Li-ion 18650 + module TP4056 | C33: 2 | D33: 900 | E33: =IF(OR(C33="",D33=""),"",C33*D33) -> 1800 | F33: Coller image ici | G33: https://aliexpress.com/item/EXEMPLE-BATT
A34: =ROW()-32 -> 2 | E34: =IF(OR(C34="",D34=""),"",C34*D34) | F34: Coller image ici
A35: =ROW()-32 -> 3 | E35: =IF(OR(C35="",D35=""),"",C35*D35) | F35: Coller image ici
A36: =ROW()-32 -> 4 | E36: =IF(OR(C36="",D36=""),"",C36*D36) | F36: Coller image ici
A37: =ROW()-32 -> 5 | E37: =IF(OR(C37="",D37=""),"",C37*D37) | F37: Coller image ici
A38: =ROW()-32 -> 6 | E38: =IF(OR(C38="",D38=""),"",C38*D38) | F38: Coller image ici
B39: Sous-total catégorie | C39: =SUM(C33:C38) -> 2 | E39: =SUM(E33:E38) -> 1800
A41: ▸ Capteurs & accessoires
A42: N° | B42: Désignation | C42: Qté | D42: Prix unitaire (FCFA) | E42: Prix total (FCFA) | F42: Image | G42: Lien AliExpress
A43: =ROW()-42 -> 1 | B43: Capteur de tension ZMPT101B | C43: 1 | D43: 1400 | E43: =IF(OR(C43="",D43=""),"",C43*D43) -> 1400 | F43: Coller image ici | G43: https://aliexpress.com/item/EXEMPLE-ZMPT
A44: =ROW()-42 -> 2 | E44: =IF(OR(C44="",D44=""),"",C44*D44) | F44: Coller image ici
A45: =ROW()-42 -> 3 | E45: =IF(OR(C45="",D45=""),"",C45*D45) | F45: Coller image ici
A46: =ROW()-42 -> 4 | E46: =IF(OR(C46="",D46=""),"",C46*D46) | F46: Coller image ici
...
